Workbook

Sheet Region
A1: id | B1: nom_region
A2: 1 | B2: Bankui
A3: 2 | B3: Djôrô
A4: 3 | B4: Goulmou
A5: 4 | B5: Guiriko
A6: 5 | B6: Kadiogo
A7: 6 | B7: Koulsé
A8: 7 | B8: Liptako
A9: 8 | B9: Nakambé
A10: 9 | B10: Nando
A11: 10 | B11: Nazinon
A12: 11 | B12: Oubri
A13: 12 | B13: Sirba
... A18: 17 | B18: Yaadga

Sheet Province
A1: id | B1: nom_province | C1: region_id | D1: nom_region
A2: 1 | B2: Mouhoun | C2: =regions!A$2 | D2: Bankui
A3: 2 | B3: Balé | C3: =regions!A$2 | D3: Bankui
A4: 3 | B4: Bamwa | C4: =regions!A$2 | D4: Bankui
A5: 4 | B5: Bougouriba | C5: =regions!A$3 | D5: Djôrô
A6: 5 | B6: Ioba | C6: =regions!A$3 | D6: Djôrô
A7: 6 | B7: Noumbiel | C7: =regions!A$3 | D7: Djôrô
A8: 7 | B8: Poni | C8: =regions!A$3 | D8: Djôrô
A9: 8 | B9: Gourma | C9: =regions!A$4 | D9: Goulmou
A10: 9 | B10: Kompienga | C10: =regions!A$4 | D10: Goulmou
A11: 10 | B11: Houet | C11: =regions!A$5 | D11: Guiriko
A12: 11 | B12: Kénédougou | C12: =regions!A$5 | D12: Guiriko
A13: 12 | B13: Tuy | C13: =regions!A$5 | D13: Guiriko
A14: 13 | B14: Kadiogo | C14: =regions!A$6 | D14: Kadiogo
A15: 14 | B15: Bam | C15: =regions!A$7 | D15: Koulsé
A16: 15 | B16: Namentenga | C16: =regions!A$7 | D16: Koulsé
A17: 16 | B17: Sandbondtenga | C17: =regions!A$7 | D17: Koulsé
A18: 17 | B18: Oudalan | C18: =regions!A$8 | D18: Liptako
A19: 18 | B19: Séno | C19: =regions!A$8 | D19: Liptako
A20: 19 | B20: Yagha | C20: =regions!A$8 | D20: Liptako
A21: 20 | B21: Boulgou | C21: =regions!A$9 | D21: Nakambé
A22: 21 | B22: Koulpelogo | C22: =regions!A$9 | D22: Nakambé
A23: 22 | B23: Kourittenga | C23: =regions!A$9 | D23: Nakambé
A24: 23 | B24: Boulkiemdé | C24: =regions!A$10 | D24: Nando
A25: 24 | B25: Sanguié | C25: =regions!A$10 | D25: Nando
A26: 25 | B26: Sissili | C26: =regions!A$10 | D26: Nando
A27: 26 | B27: Ziro | C27: =regions!A$10 | D27: Nando
A28: 27 | B28: Bazèga | C28: =regions!A$11 | D28: Nazinon
A29: 28 | B29: Nahouri | C29: =regions!A$11 | D29: Nazinon
A30: 29 | B30: Zoundwéogo | C30: =regions!A$11 | D30: Nazinon
A31: 30 | B31: Bassitenga | C31: =regions!A$12 | D31: Oubri
A32: 31 | B32: Ganzourgou | C32: =regions!A$12 | D32: Oubri
A33: 32 | B33: Kourwéogo | C33: =regions!A$12 | D33: Oubri
A34: 33 | B34: Gnagna | C34: =regions!A$13 | D34: Sirba
A35: 34 | B35: Komondjari | C35: =regions!A$13 | D35: Sirba
A36: 35 | B36: Djelgodji | C36: =regions!A$14 | D36: Soum
A37: 36 | B37: Karo-Peli | C37: =regions!A$14 | D37: Soum
A38: 37 | B38: Koosin | C38: =regions!A$15 | D38: Sourou
A39: 38 | B39: Nayala | C39: =regions!A$15 | D39: Sourou
A40: 39 | B40: Sourou | C40: =regions!A$15 | D40: Sourou
...

Sheet Commune
A1: id | B1: nom_commune | C1: province_id | D1: nom_province | E1: type_commune
A2: 1 | B2: Bondokuy | C2: 1 | D2: Mouhoun
A3: 2 | B3: Dédougou | C3: 1 | D3: Mouhoun | E3: Urbaine
A4: 3 | B4: Douroula | C4: 1 | D4: Mouhoun
A5: 4 | B5: Kona | C5: 1 | D5: Mouhoun
A6: 5 | B6: Ouarkoye | C6: 1 | D6: Mouhoun
A7: 6 | B7: Safané | C7: 1 | D7: Mouhoun
A8: 7 | B8: Tchériba | C8: 1 | D8: Mouhoun | E8: Urbaine
A9: 8 | B9: Bagassi | C9: 2 | D9: Balé
A10: 9 | B10: Bana | C10: 2 | D10: Balé
A11: 10 | B11: Boromo | C11: 2 | D11: Balé | E11: Urbaine
A12: 11 | B12: Fara | C12: 2 | D12: Balé
A13: 12 | B13: Pa | C13: 2 | D13: Balé
A14: 13 | B14: Pompoï | C14: 2 | D14: Balé
A15: 14 | B15: Poura | C15: 2 | D15: Balé
A16: 15 | B16: Oury | C16: 2 | D16: Balé
A17: 16 | B17: Siby | C17: 2 | D17: Balé
A18: 17 | B18: Yaho | C18: 2 | D18: Balé
A19: 18 | B19: Balavé | C19: 3 | D19: Bamwa
A20: 19 | B20: Kouka | C20: 3 | D20: Bamwa
A21: 20 | B21: Sami | C21: 3 | D21: Bamwa
A22: 21 | B22: Sanaba | C22: 3 | D22: Bamwa
A23: 22 | B23: Solenzo | C23: 3 | D23: Bamwa | E23: Urbaine
A24: 23 | B24: Tansila | C24: 3 | D24: Bamwa
A25: 24 | B25: Gbondjigui | C25: 4 | D25: Bougouriba
A26: 25 | B26: Diébougou | C26: 4 | D26: Bougouriba
A27: 26 | B27: Dolo | C27: 4 | D27: Bougouriba
A28: 27 | B28: Nioronioro | C28: 4 | D28: Bougouriba
A29: 28 | B29: Tiankoura | C29: 4 | D29: Bougouriba
A30: 29 | B30: Dano | C30: 5 | D30: Ioba
A31: 30 | B31: Dissihn | C31: 5 | D31: Ioba
A32: 31 | B32: Guéguéré | C32: 5 | D32: Ioba
A33: 32 | B33: Koper | C33: 5 | D33: Ioba
A34: 33 | B34: Niégo | C34: 5 | D34: Ioba
A35: 34 | B35: Oronkua | C35: 5 | D35: Ioba
... A62: 61 | B62: Bama | C62: 10 | D62: Houet
A63: 62 | B63: Bobo-Dioulasso | C63: 10 | D63: Houet | E63: Statut particulier
A64: 63 | B64: Dandé | C64: 10 | D64: Houet
A65: 64 | B65: Karangasso-Sambla | C65: 10 | D65: Houet
A66: 65 | B66: Karangasso-Viguè | C66: 10 | D66: Houet
...

Sheet Type_Commune
A1: id | B1: label
A2: 1 | B2: Rurale
A3: 2 | B3: Urbaine
A4: 3 | B4: Statut particulier

Sheet Type_Mairie
A1: id | B1: label
A2: 1 | B2: Centrale
A3: 2 | B3: Arrondissement
